Running Funannotate fix on predict/predict_results/Datura_stramonium_3.gbk
[11:59 AM]: OS: linux2, 64 cores, ~ 528 GB RAM. Python: 2.7.15
[11:59 AM]: Running funannotate v1.6.0-98d4d3f
-------------------------------------------------------
Traceback (most recent call last):
  File "/bigdata/operations/pkgadmin/opt/linux/centos/7.x/x86_64/pkgs/funannotate/git-live/util/updateGBK.py", line 58, in <module>
    lib.tblfilter(args.tbl, args.drop, os.path.join(basedir, 'tbl2asn', 'genome.tbl'))
  File "/bigdata/operations/pkgadmin/opt/linux/centos/7.x/x86_64/pkgs/funannotate/git-live/lib/library.py", line 1723, in tblfilter
    with open(remove, 'rU') as file:
IOError: [Errno 2] No such file or directory: 'predict/predict_results/Datura_stramonium.models-to-delete.txt'
